Workbook

Sheet clean_data
A1: user_id | B1: signup_date | C1: experiment_group | D1: region | E1: device_type | F1: device_type_clean | G1: traffic_source | H1: traffic_source_clean | I1: plan_type | J1: visited_landing_page | K1: started_trial | L1: completed_onboarding | M1: converted_to_paid | N1: revenue_30d | O1: support_tickets_30d | P1: support_ticket_user | Q1: refund_requested | R1: days_to_convert | S1: engagement_score | T1: engagement_score_clean
A2: USR-100001 | B2: 45732 | C2: Control | D2: North | E2: Desktop | F2: =IF(E2="","Unknown",E2) -> Desktop | G2: Email | H2: =IF(G2="","Unknown",G2) -> Email | I2: Basic | J2: 0 | K2: 0 | L2: 0 | M2: 0 | N2: 0 | O2: 0 | P2: =IF(O2>0,1,0) -> 0 | Q2: 0 | S2: 45.7 | T2: =IF(S2="",MEDIAN($S$2:$S$1409),S2) -> 45.7
A3: USR-100002 | B3: 45724 | C3: Control | D3: West | E3: Mobile | F3: =IF(E3="","Unknown",E3) -> Mobile | G3: Organic | H3: =IF(G3="","Unknown",G3) -> Organic | I3: Free | J3: 1 | K3: 0 | L3: 0 | M3: 0 | N3: 0 | O3: 0 | P3: =IF(O3>0,1,0) -> 0 | Q3: 0 | S3: 48.6 | T3: =IF(S3="",MEDIAN($S$2:$S$1409),S3) -> 48.6
A4: USR-100003 | B4: 45771 | C4: Control | D4: East | E4: Mobile | F4: =IF(E4="","Unknown",E4) -> Mobile | G4: Paid Search | H4: =IF(G4="","Unknown",G4) -> Paid Search | I4: Premium | J4: 1 | K4: 0 | L4: 0 | M4: 0 | N4: 0 | O4: 1 | P4: =IF(O4>0,1,0) -> 1 | Q4: 0 | S4: 35.4 | T4: =IF(S4="",MEDIAN($S$2:$S$1409),S4) -> 35.4
A5: USR-100004 | B5: 45781 | C5: Control | D5: South | E5: Mobile | F5: =IF(E5="","Unknown",E5) -> Mobile | G5: Email | H5: =IF(G5="","Unknown",G5) -> Email | I5: Basic | J5: 1 | K5: 0 | L5: 0 | M5: 0 | N5: 0 | O5: 0 | P5: =IF(O5>0,1,0) -> 0 | Q5: 0 | S5: 64.6 | T5: =IF(S5="",MEDIAN($S$2:$S$1409),S5) -> 64.6
A6: USR-100005 | B6: 45700 | C6: Control | D6: North | E6: Tablet | F6: =IF(E6="","Unknown",E6) -> Tablet | G6: Organic | H6: =IF(G6="","Unknown",G6) -> Organic | I6: Free | J6: 0 | K6: 0 | L6: 0 | M6: 0 | N6: 0 | O6: 0 | P6: =IF(O6>0,1,0) -> 0 | Q6: 0 | S6: 66.6 | T6: =IF(S6="",MEDIAN($S$2:$S$1409),S6) -> 66.6
A7: USR-100006 | B7: 45685 | C7: Control | D7: East | E7: Mobile | F7: =IF(E7="","Unknown",E7) -> Mobile | G7: Organic | H7: =IF(G7="","Unknown",G7) -> Organic | I7: Premium | J7: 1 | K7: 0 | L7: 0 | M7: 0 | N7: 0 | O7: 0 | P7: =IF(O7>0,1,0) -> 0 | Q7: 0 | S7: 40.8 | T7: =IF(S7="",MEDIAN($S$2:$S$1409),S7) -> 40.8
A8: USR-100007 | B8: 45755 | C8: Control | D8: East | E8: Mobile | F8: =IF(E8="","Unknown",E8) -> Mobile | G8: Paid Search | H8: =IF(G8="","Unknown",G8) -> Paid Search | I8: Basic | J8: 1 | K8: 1 | L8: 0 | M8: 0 | N8: 0 | O8: 0 | P8: =IF(O8>0,1,0) -> 0 | Q8: 0 | S8: 57.1 | T8: =IF(S8="",MEDIAN($S$2:$S$1409),S8) -> 57.1
A9: USR-100008 | B9: 45794 | C9: Control | D9: South | E9: Mobile | F9: =IF(E9="","Unknown",E9) -> Mobile | G9: Paid Search | H9: =IF(G9="","Unknown",G9) -> Paid Search | I9: Free | J9: 0 | K9: 0 | L9: 0 | M9: 0 | N9: 0 | O9: 0 | P9: =IF(O9>0,1,0) -> 0 | Q9: 0 | S9: 36.4 | T9: =IF(S9="",MEDIAN($S$2:$S$1409),S9) -> 36.4
A10: USR-100009 | B10: 45711 | C10: Control | D10: South | E10: Tablet | F10: =IF(E10="","Unknown",E10) -> Tablet | G10: Referral | H10: =IF(G10="","Unknown",G10) -> Referral | I10: Basic | J10: 0 | K10: 0 | L10: 0 | M10: 0 | N10: 0 | O10: 0 | P10: =IF(O10>0,1,0) -> 0 | Q10: 0 | S10: 55.4 | T10: =IF(S10="",MEDIAN($S$2:$S$1409),S10) -> 55.4
A11: USR-100010 | B11: 45806 | C11: Control | D11: West | E11: Desktop | F11: =IF(E11="","Unknown",E11) -> Desktop | G11: Social | H11: =IF(G11="","Unknown",G11) -> Social | I11: Free | J11: 1 | K11: 0 | L11: 0 | M11: 0 | N11: 0 | O11: 0 | P11: =IF(O11>0,1,0) -> 0 | Q11: 0 | S11: 57.3 | T11: =IF(S11="",MEDIAN($S$2:$S$1409),S11) -> 57.3
A12: USR-100011 | B12: 45777 | C12: Control | D12: East | E12: Mobile | F12: =IF(E12="","Unknown",E12) -> Mobile | G12: Paid Search | H12: =IF(G12="","Unknown",G12) -> Paid Search | I12: Basic | J12: 1 | K12: 1 | L12: 1 | M12: 0 | N12: 0 | O12: 0 | P12: =IF(O12>0,1,0) -> 0 | Q12: 0 | S12: 63.6 | T12: =IF(S12="",MEDIAN($S$2:$S$1409),S12) -> 63.6
A13: USR-100012 | B13: 45732 | C13: Control | D13: East | E13: Mobile | F13: =IF(E13="","Unknown",E13) -> Mobile | G13: Social | H13: =IF(G13="","Unknown",G13) -> Social | I13: Premium | J13: 1 | K13: 1 | L13: 1 | M13: 0 | N13: 0 | O13: 1 | P13: =IF(O13>0,1,0) -> 1 | Q13: 0 | S13: 80.4 | T13: =IF(S13="",MEDIAN($S$2:$S$1409),S13) -> 80.4
... A60: USR-100059 | B60: 45761 | C60: Control | D60: North | E60: Mobile | F60: =IF(E60="","Unknown",E60) -> Mobile | G60: Social | H60: =IF(G60="","Unknown",G60) -> Social | I60: Free | J60: 0 | K60: 0 | L60: 0 | M60: 0 | N60: 0 | O60: 2 | P60: =IF(O60>0,1,0) -> 1 | Q60: 0 | S60: 48.9 | T60: =IF(S60="",MEDIAN($S$2:$S$1409),S60) -> 48.9
A61: USR-100060 | B61: 45658 | C61: Control | D61: West | E61: Mobile | F61: =IF(E61="","Unknown",E61) -> Mobile | G61: Social | H61: =IF(G61="","Unknown",G61) -> Social | I61: Free | J61: 1 | K61: 1 | L61: 1 | M61: 1 | N61: 240.42 | O61: 0 | P61: =IF(O61>0,1,0) -> 0 | Q61: 0 | R61: 16 | S61: 56.5 | T61: =IF(S61="",MEDIAN($S$2:$S$1409),S61) -> 56.5
A62: USR-100061 | B62: 45749 | C62: Control | D62: South | E62: Mobile | F62: =IF(E62="","Unknown",E62) -> Mobile | G62: Referral | H62: =IF(G62="","Unknown",G62) -> Referral | I62: Free | J62: 1 | K62: 0 | L62: 0 | M62: 0 | N62: 0 | O62: 0 | P62: =IF(O62>0,1,0) -> 0 | Q62: 0 | S62: 53.7 | T62: =IF(S62="",MEDIAN($S$2:$S$1409),S62) -> 53.7
A63: USR-100062 | B63: 45745 | C63: Control | D63: North | E63: Mobile | F63: =IF(E63="","Unknown",E63) -> Mobile | G63: Social | H63: =IF(G63="","Unknown",G63) -> Social | I63: Premium | J63: 0 | K63: 0 | L63: 0 | M63: 0 | N63: 0 | O63: 0 | P63: =IF(O63>0,1,0) -> 0 | Q63: 0 | S63: 62.2 | T63: =IF(S63="",MEDIAN($S$2:$S$1409),S63) -> 62.2
A64: USR-100063 | B64: 45792 | C64: Control | D64: South | E64: Desktop | F64: =IF(E64="","Unknown",E64) -> Desktop | G64: Organic | H64: =IF(G64="","Unknown",G64) -> Organic | I64: Free | J64: 1 | K64: 0 | L64: 0 | M64: 0 | N64: 0 | O64: 0 | P64: =IF(O64>0,1,0) -> 0 | Q64: 0 | S64: 50.2 | T64: =IF(S64="",MEDIAN($S$2:$S$1409),S64) -> 50.2
A65: USR-100064 | B65: 45758 | C65: Control | D65: North | E65: Mobile | F65: =IF(E65="","Unknown",E65) -> Mobile | G65: Organic | H65: =IF(G65="","Unknown",G65) -> Organic | I65: Basic | J65: 1 | K65: 0 | L65: 0 | M65: 0 | N65: 0 | O65: 0 | P65: =IF(O65>0,1,0) -> 0 | Q65: 0 | S65: 74.3 | T65: =IF(S65="",MEDIAN($S$2:$S$1409),S65) -> 74.3
A66: USR-100065 | B66: 45723 | C66: Control | D66: South | E66: Desktop | F66: =IF(E66="","Unknown",E66) -> Desktop | G66: Paid Search | H66: =IF(G66="","Unknown",G66) -> Paid Search | I66: Free | J66: 1 | K66: 0 | L66: 0 | M66: 0 | N66: 0 | O66: 0 | P66: =IF(O66>0,1,0) -> 0 | Q66: 0 | S66: 58 | T66: =IF(S66="",MEDIAN($S$2:$S$1409),S66) -> 58
A67: USR-100066 | B67: 45807 | C67: Control | D67: South | E67: Mobile | F67: =IF(E67="","Unknown",E67) -> Mobile | G67: Organic | H67: =IF(G67="","Unknown",G67) -> Organic | I67: Free | J67: 0 | K67: 0 | L67: 0 | M67: 0 | N67: 0 | O67: 0 | P67: =IF(O67>0,1,0) -> 0 | Q67: 0 | S67: 46.7 | T67: =IF(S67="",MEDIAN($S$2:$S$1409),S67) -> 46.7
A68: USR-100067 | B68: 45664 | C68: Control | D68: South | E68: Desktop | F68: =IF(E68="","Unknown",E68) -> Desktop | G68: Organic | H68: =IF(G68="","Unknown",G68) -> Organic | I68: Premium | J68: 1 | K68: 0 | L68: 0 | M68: 0 | N68: 0 | O68: 1 | P68: =IF(O68>0,1,0) -> 1 | Q68: 0 | S68: 49.6 | T68: =IF(S68="",MEDIAN($S$2:$S$1409),S68) -> 49.6
A69: USR-100068 | B69: 45785 | C69: Control | D69: West | E69: Mobile | F69: =IF(E69="","Unknown",E69) -> Mobile | G69: Social | H69: =IF(G69="","Unknown",G69) -> Social | I69: Free | J69: 0 | K69: 0 | L69: 0 | M69: 0 | N69: 0 | O69: 0 | P69: =IF(O69>0,1,0) -> 0 | Q69: 0 | S69: 60.4 | T69: =IF(S69="",MEDIAN($S$2:$S$1409),S69) -> 60.4
A70: USR-100069 | B70: 45735 | C70: Control | D70: East | E70: Desktop | F70: =IF(E70="","Unknown",E70) -> Desktop | G70: Email | H70: =IF(G70="","Unknown",G70) -> Email | I70: Free | J70: 1 | K70: 1 | L70: 1 | M70: 0 | N70: 0 | O70: 0 | P70: =IF(O70>0,1,0) -> 0 | Q70: 0 | S70: 55.3 | T70: =IF(S70="",MEDIAN($S$2:$S$1409),S70) -> 55.3
A71: USR-100070 | B71: 45793 | C71: Control | D71: North | E71: Desktop | F71: =IF(E71="","Unknown",E71) -> Desktop | G71: Organic | H71: =IF(G71="","Unknown",G71) -> Organic | I71: Free | J71: 0 | K71: 0 | L71: 0 | M71: 0 | N71: 0 | O71: 0 | P71: =IF(O71>0,1,0) -> 0 | Q71: 0 | S71: 56.2 | T71: =IF(S71="",MEDIAN($S$2:$S$1409),S71) -> 56.2
A72: USR-100071 | B72: 45724 | C72: Control | D72: West | E72: Mobile | F72: =IF(E72="","Unknown",E72) -> Mobile | G72: Email | H72: =IF(G72="","Unknown",G72) -> Email | I72: Free | J72: 0 | K72: 0 | L72: 0 | M72: 0 | N72: 0 | O72: 0 | P72: =IF(O72>0,1,0) -> 0 | Q72: 0 | S72: 29.4 | T72: =IF(S72="",MEDIAN($S$2:$S$1409),S72) -> 29.4
A73: USR-100072 | B73: 45724 | C73: Control | D73: East | E73: Mobile | F73: =IF(E73="","Unknown",E73) -> Mobile | G73: Email | H73: =IF(G73="","Unknown",G73) -> Email | I73: Free | J73: 1 | K73: 0 | L73: 0 | M73: 0 | N73: 0 | O73: 0 | P73: =IF(O73>0,1,0) -> 0 | Q73: 0 | S73: 54.2 | T73: =IF(S73="",MEDIAN($S$2:$S$1409),S73) -> 54.2
... A79: USR-100078 | B79: 45673 | C79: Control | D79: North | E79: Mobile | F79: =IF(E79="","Unknown",E79) -> Mobile | G79: Organic | H79: =IF(G79="","Unknown",G79) -> Organic | I79: Free | J79: 0 | K79: 0 | L79: 0 | M79: 0 | N79: 0 | O79: 2 | P79: =IF(O79>0,1,0) -> 1 | Q79: 0 | S79: 48.4 | T79: =IF(S79="",MEDIAN($S$2:$S$1409),S79) -> 48.4
A80: USR-100079 | B80: 45708 | C80: Control | D80: West | E80: Desktop | F80: =IF(E80="","Unknown",E80) -> Desktop | G80: Organic | H80: =IF(G80="","Unknown",G80) -> Organic | I80: Free | J80: 1 | K80: 1 | L80: 1 | M80: 1 | N80: 457.51 | O80: 0 | P80: =IF(O80>0,1,0) -> 0 | Q80: 0 | R80: 7 | S80: 38 | T80: =IF(S80="",MEDIAN($S$2:$S$1409),S80) -> 38
A81: USR-100080 | B81: 45798 | C81: Control | D81: East | E81: Mobile | F81: =IF(E81="","Unknown",E81) -> Mobile | G81: Social | H81: =IF(G81="","Unknown",G81) -> Social | I81: Free | J81: 1 | K81: 0 | L81: 0 | M81: 0 | N81: 0 | O81: 0 | P81: =IF(O81>0,1,0) -> 0 | Q81: 0 | S81: 44.2 | T81: =IF(S81="",MEDIAN($S$2:$S$1409),S81) -> 44.2
A82: USR-100081 | B82: 45785 | C82: Control | D82: South | E82: Mobile | F82: =IF(E82="","Unknown",E82) -> Mobile | G82: Organic | H82: =IF(G82="","Unknown",G82) -> Organic | I82: Free | J82: 1 | K82: 1 | L82: 1 | M82: 0 | N82: 0 | O82: 0 | P82: =IF(O82>0,1,0) -> 0 | Q82: 0 | S82: 81.2 | T82: =IF(S82="",MEDIAN($S$2:$S$1409),S82) -> 81.2
A83: USR-100082 | B83: 45724 | C83: Control | D83: South | E83: Mobile | F83: =IF(E83="","Unknown",E83) -> Mobile | G83: Referral | H83: =IF(G83="","Unknown",G83) -> Referral | I83: Free | J83: 1 | K83: 1 | L83: 0 | M83: 0 | N83: 0 | O83: 0 | P83: =IF(O83>0,1,0) -> 0 | Q83: 0 | S83: 63.8 | T83: =IF(S83="",MEDIAN($S$2:$S$1409),S83) -> 63.8
A84: USR-100083 | B84: 45748 | C84: Control | D84: South | E84: Desktop | F84: =IF(E84="","Unknown",E84) -> Desktop | G84: Email | H84: =IF(G84="","Unknown",G84) -> Email | I84: Free | J84: 0 | K84: 0 | L84: 0 | M84: 0 | N84: 0 | O84: 0 | P84: =IF(O84>0,1,0) -> 0 | Q84: 0 | S84: 64.7 | T84: =IF(S84="",MEDIAN($S$2:$S$1409),S84) -> 64.7
A85: USR-100084 | B85: 45719 | C85: Control | D85: West | E85: Mobile | F85: =IF(E85="","Unknown",E85) -> Mobile | G85: Social | H85: =IF(G85="","Unknown",G85) -> Social | I85: Basic | J85: 0 | K85: 0 | L85: 0 | M85: 0 | N85: 0 | O85: 0 | P85: =IF(O85>0,1,0) -> 0 | Q85: 0 | S85: 60.4 | T85: =IF(S85="",MEDIAN($S$2:$S$1409),S85) -> 60.4
A86: USR-100085 | B86: 45763 | C86: Control | D86: South | E86: Mobile | F86: =IF(E86="","Unknown",E86) -> Mobile | G86: Paid Search | H86: =IF(G86="","Unknown",G86) -> Paid Search | I86: Free | J86: 0 | K86: 0 | L86: 0 | M86: 0 | N86: 0 | O86: 0 | P86: =IF(O86>0,1,0) -> 0 | Q86: 0 | S86: 66.6 | T86: =IF(S86="",MEDIAN($S$2:$S$1409),S86) -> 66.6
A87: USR-100086 | B87: 45666 | C87: Control | D87: North | E87: Desktop | F87: =IF(E87="","Unknown",E87) -> Desktop | G87: Organic | H87: =IF(G87="","Unknown",G87) -> Organic | I87: Free | J87: 1 | K87: 0 | L87: 0 | M87: 0 | N87: 0 | O87: 0 | P87: =IF(O87>0,1,0) -> 0 | Q87: 0 | S87: 50.9 | T87: =IF(S87="",MEDIAN($S$2:$S$1409),S87) -> 50.9
A88: USR-100087 | B88: 45679 | C88: Control | D88: West | E88: Desktop | F88: =IF(E88="","Unknown",E88) -> Desktop | G88: Social | H88: =IF(G88="","Unknown",G88) -> Social | I88: Basic | J88: 0 | K88: 0 | L88: 0 | M88: 0 | N88: 0 | O88: 0 | P88: =IF(O88>0,1,0) -> 0 | Q88: 0 | S88: 51 | T88: =IF(S88="",MEDIAN($S$2:$S$1409),S88) -> 51
A89: USR-100088 | B89: 45777 | C89: Control | D89: South | E89: Mobile | F89: =IF(E89="","Unknown",E89) -> Mobile | G89: Email | H89: =IF(G89="","Unknown",G89) -> Email | I89: Premium | J89: 0 | K89: 0 | L89: 0 | M89: 0 | N89: 0 | O89: 0 | P89: =IF(O89>0,1,0) -> 0 | Q89: 0 | S89: 65.8 | T89: =IF(S89="",MEDIAN($S$2:$S$1409),S89) -> 65.8
A90: USR-100089 | B90: 45772 | C90: Control | D90: North | E90: Mobile | F90: =IF(E90="","Unknown",E90) -> Mobile | G90: Referral | H90: =IF(G90="","Unknown",G90) -> Referral | I90: Basic | J90: 1 | K90: 0 | L90: 0 | M90: 0 | N90: 0 | O90: 0 | P90: =IF(O90>0,1,0) -> 0 | Q90: 0 | S90: 61.8 | T90: =IF(S90="",MEDIAN($S$2:$S$1409),S90) -> 61.8
A91: USR-100090 | B91: 45689 | C91: Control | D91: North | E91: Mobile | F91: =IF(E91="","Unknown",E91) -> Mobile | G91: Organic | H91: =IF(G91="","Unknown",G91) -> Organic | I91: Basic | J91: 1 | K91: 0 | L91: 0 | M91: 0 | N91: 0 | O91: 0 | P91: =IF(O91>0,1,0) -> 0 | Q91: 0 | S91: 54.5 | T91: =IF(S91="",MEDIAN($S$2:$S$1409),S91) -> 54.5
...

Sheet Control_vs_Treatment
A1: Group | B1: User count | C1: Landing page visit rate | D1: Trial start rate | E1: Onboarding completion rate | F1: Paid conversion rate | G1: Average revenue per user | H1: Average revenue per converted user | I1: Refund rate | J1: Support ticket rate | K1: Average engagement score | L1: Average days to convert
A2: Control | B2: =COUNTIF(clean_data!$C$2:$C$1409,"Control") -> 693 | C2: =SUMIFS(clean_data!$J$2:$J$1409,clean_data!$C$2:$C$1409,"Control")/COUNTIF(clean_data!$C$2:$C$1409,"Control") -> 0.63636364 | D2: =SUMIFS(clean_data!$K$2:$K$1409,clean_data!$C$2:$C$1409,"Control")/COUNTIF(clean_data!$C$2:$C$1409,"Control") -> 0.25108225 | E2: =SUMIFS(clean_data!$L$2:$L$1409,clean_data!$C$2:$C$1409,"Control")/COUNTIF(clean_data!$C$2:$C$1409,"Control") -> 0.15584416 | F2: =SUMIFS(clean_data!$M$2:$M$1409,clean_data!$C$2:$C$1409,"Control")/COUNTIF(clean_data!$C$2:$C$1409,"Control") -> 0.031746032 | G2: =SUMIFS(clean_data!$N$2:$N$1409,clean_data!$C$2:$C$1409,"Control")/COUNTIF(clean_data!$C$2:$C$1409,"Control") -> 51.749322 | H2: =SUMIFS(clean_data!$N$2:$N$1409,clean_data!$C$2:$C$1409,"Control",clean_data!$M$2:$M$1409,1)/COUNTIFS(clean_data!$C$2:$C$1409,"Control",clean_data!$M$2:$M$1409,1) -> 1630.1036 | I2: =SUMIFS(clean_data!$Q$2:$Q$1409,clean_data!$C$2:$C$1409,"Control")/COUNTIF(clean_data!$C$2:$C$1409,"Control") -> 0 | J2: =SUMIFS(clean_data!$P$2:$P$1409,clean_data!$C$2:$C$1409,"Control")/COUNTIF(clean_data!$C$2:$C$1409,"Control") -> 0.14718615 | K2: =AVERAGEIFS(clean_data!$T$2:$T$1409,clean_data!$C$2:$C$1409,"Control") -> 57.051082 | L2: =AVERAGEIFS(clean_data!$R$2:$R$1409,clean_data!$C$2:$C$1409,"Control",clean_data!$M$2:$M$1409,1) -> 8.8636364
A3: Treatment | B3: =COUNTIF(clean_data!$C$2:$C$1409,"Treatment") -> 715 | C3: =SUMIFS(clean_data!$J$2:$J$1409,clean_data!$C$2:$C$1409,"Treatment")/COUNTIF(clean_data!$C$2:$C$1409,"Treatment") -> 0.72587413 | D3: =SUMIFS(clean_data!$K$2:$K$1409,clean_data!$C$2:$C$1409,"Treatment")/COUNTIF(clean_data!$C$2:$C$1409,"Treatment") -> 0.29090909 | E3: =SUMIFS(clean_data!$L$2:$L$1409,clean_data!$C$2:$C$1409,"Treatment")/COUNTIF(clean_data!$C$2:$C$1409,"Treatment") -> 0.21258741 | F3: =SUMIFS(clean_data!$M$2:$M$1409,clean_data!$C$2:$C$1409,"Treatment")/COUNTIF(clean_data!$C$2:$C$1409,"Treatment") -> 0.06993007 | G3: =SUMIFS(clean_data!$N$2:$N$1409,clean_data!$C$2:$C$1409,"Treatment")/COUNTIF(clean_data!$C$2:$C$1409,"Treatment") -> 53.875119 | H3: =SUMIFS(clean_data!$N$2:$N$1409,clean_data!$C$2:$C$1409,"Treatment",clean_data!$M$2:$M$1409,1)/COUNTIFS(clean_data!$C$2:$C$1409,"Treatment",clean_data!$M$2:$M$1409,1) -> 770.4142 | I3: =SUMIFS(clean_data!$Q$2:$Q$1409,clean_data!$C$2:$C$1409,"Treatment")/COUNTIF(clean_data!$C$2:$C$1409,"Treatment") -> 0.0041958042 | J3: =SUMIFS(clean_data!$P$2:$P$1409,clean_data!$C$2:$C$1409,"Treatment")/COUNTIF(clean_data!$C$2:$C$1409,"Treatment") -> 0.24755245 | K3: =AVERAGEIFS(clean_data!$T$2:$T$1409,clean_data!$C$2:$C$1409,"Treatment") -> 62.898042 | L3: =AVERAGEIFS(clean_data!$R$2:$R$1409,clean_data!$C$2:$C$1409,"Treatment",clean_data!$M$2:$M$1409,1) -> 6.4
B4: Number of users in each group | C4: Users who visited landing page / total users | D4: Users who started trial / total users | E4: Users who completed onboarding / total users | F4: Users converted to paid / total users | G4: Total revenue / total users | H4: Revenue / converted users | I4: Refund requests / total users | J4: Users with support tickets / total users | K4: Average score by group | L4: Average days for users who converted

Sheet Segment_Analysis
A1: Region
A2: Segment type | B2: Segment | C2: Group | D2: User count | E2: Paid conversion rate | F2: Trial start rate | G2: ARPU | H2: Refund rate | I2: Support ticket rate | J2: Avg engagement score
A3: Region | B3: North | C3: Control | D3: =COUNTIFS(clean_data!$D$2:$D$1409,"North",clean_data!$C$2:$C$1409,"Control") -> 203 | E3: =IFERROR(SUMIFS(clean_data!$M$2:$M$1409,clean_data!$D$2:$D$1409,"North",clean_data!$C$2:$C$1409,"Control")/D3,"") -> 0.034482759 | F3: =IFERROR(SUMIFS(clean_data!$K$2:$K$1409,clean_data!$D$2:$D$1409,"North",clean_data!$C$2:$C$1409,"Control")/D3,"") -> 0.20689655 | G3: =IFERROR(SUMIFS(clean_data!$N$2:$N$1409,clean_data!$D$2:$D$1409,"North",clean_data!$C$2:$C$1409,"Control")/D3,"") -> 83.667586 | H3: =IFERROR(SUMIFS(clean_data!$Q$2:$Q$1409,clean_data!$D$2:$D$1409,"North",clean_data!$C$2:$C$1409,"Control")/D3,"") -> 0 | I3: =IFERROR(SUMIFS(clean_data!$P$2:$P$1409,clean_data!$D$2:$D$1409,"North",clean_data!$C$2:$C$1409,"Control")/D3,"") -> 0.15270936 | J3: =IFERROR(AVERAGEIFS(clean_data!$T$2:$T$1409,clean_data!$D$2:$D$1409,"North",clean_data!$C$2:$C$1409,"Control"),"") -> 57.57931
A4: Region | B4: North | C4: Treatment | D4: =COUNTIFS(clean_data!$D$2:$D$1409,"North",clean_data!$C$2:$C$1409,"Treatment") -> 180 | E4: =IFERROR(SUMIFS(clean_data!$M$2:$M$1409,clean_data!$D$2:$D$1409,"North",clean_data!$C$2:$C$1409,"Treatment")/D4,"") -> 0.088888889 | F4: =IFERROR(SUMIFS(clean_data!$K$2:$K$1409,clean_data!$D$2:$D$1409,"North",clean_data!$C$2:$C$1409,"Treatment")/D4,"") -> 0.29444444 | G4: =IFERROR(SUMIFS(clean_data!$N$2:$N$1409,clean_data!$D$2:$D$1409,"North",clean_data!$C$2:$C$1409,"Treatment")/D4,"") -> 80.9675 | H4: =IFERROR(SUMIFS(clean_data!$Q$2:$Q$1409,clean_data!$D$2:$D$1409,"North",clean_data!$C$2:$C$1409,"Treatment")/D4,"") -> 0 | I4: =IFERROR(SUMIFS(clean_data!$P$2:$P$1409,clean_data!$D$2:$D$1409,"North",clean_data!$C$2:$C$1409,"Treatment")/D4,"") -> 0.22777778 | J4: =IFERROR(AVERAGEIFS(clean_data!$T$2:$T$1409,clean_data!$D$2:$D$1409,"North",clean_data!$C$2:$C$1409,"Treatment"),"") -> 63.081667
A5: Region | B5: South | C5: Control | D5: =COUNTIFS(clean_data!$D$2:$D$1409,"South",clean_data!$C$2:$C$1409,"Control") -> 184 | E5: =IFERROR(SUMIFS(clean_data!$M$2:$M$1409,clean_data!$D$2:$D$1409,"South",clean_data!$C$2:$C$1409,"Control")/D5,"") -> 0.032608696 | F5: =IFERROR(SUMIFS(clean_data!$K$2:$K$1409,clean_data!$D$2:$D$1409,"South",clean_data!$C$2:$C$1409,"Control")/D5,"") -> 0.22282609 | G5: =IFERROR(SUMIFS(clean_data!$N$2:$N$1409,clean_data!$D$2:$D$1409,"South",clean_data!$C$2:$C$1409,"Control")/D5,"") -> 76.033098 | H5: =IFERROR(SUMIFS(clean_data!$Q$2:$Q$1409,clean_data!$D$2:$D$1409,"South",clean_data!$C$2:$C$1409,"Control")/D5,"") -> 0 | I5: =IFERROR(SUMIFS(clean_data!$P$2:$P$1409,clean_data!$D$2:$D$1409,"South",clean_data!$C$2:$C$1409,"Control")/D5,"") -> 0.14130435 | J5: =IFERROR(AVERAGEIFS(clean_data!$T$2:$T$1409,clean_data!$D$2:$D$1409,"South",clean_data!$C$2:$C$1409,"Control"),"") -> 56.953804
A6: Region | B6: South | C6: Treatment | D6: =COUNTIFS(clean_data!$D$2:$D$1409,"South",clean_data!$C$2:$C$1409,"Treatment") -> 184 | E6: =IFERROR(SUMIFS(clean_data!$M$2:$M$1409,clean_data!$D$2:$D$1409,"South",clean_data!$C$2:$C$1409,"Treatment")/D6,"") -> 0.076086957 | F6: =IFERROR(SUMIFS(clean_data!$K$2:$K$1409,clean_data!$D$2:$D$1409,"South",clean_data!$C$2:$C$1409,"Treatment")/D6,"") -> 0.33152174 | G6: =IFERROR(SUMIFS(clean_data!$N$2:$N$1409,clean_data!$D$2:$D$1409,"South",clean_data!$C$2:$C$1409,"Treatment")/D6,"") -> 47.001685 | H6: =IFERROR(SUMIFS(clean_data!$Q$2:$Q$1409,clean_data!$D$2:$D$1409,"South",clean_data!$C$2:$C$1409,"Treatment")/D6,"") -> 0 | I6: =IFERROR(SUMIFS(clean_data!$P$2:$P$1409,clean_data!$D$2:$D$1409,"South",clean_data!$C$2:$C$1409,"Treatment")/D6,"") -> 0.22282609 | J6: =IFERROR(AVERAGEIFS(clean_data!$T$2:$T$1409,clean_data!$D$2:$D$1409,"South",clean_data!$C$2:$C$1409,"Treatment"),"") -> 62.133696
A7: Region | B7: East | C7: Control | D7: =COUNTIFS(clean_data!$D$2:$D$1409,"East",clean_data!$C$2:$C$1409,"Control") -> 158 | E7: =IFERROR(SUMIFS(clean_data!$M$2:$M$1409,clean_data!$D$2:$D$1409,"East",clean_data!$C$2:$C$1409,"Control")/D7,"") -> 0.025316456 | F7: =IFERROR(SUMIFS(clean_data!$K$2:$K$1409,clean_data!$D$2:$D$1409,"East",clean_data!$C$2:$C$1409,"Control")/D7,"") -> 0.29746835 | G7: =IFERROR(SUMIFS(clean_data!$N$2:$N$1409,clean_data!$D$2:$D$1409,"East",clean_data!$C$2:$C$1409,"Control")/D7,"") -> 18.116076 | H7: =IFERROR(SUMIFS(clean_data!$Q$2:$Q$1409,clean_data!$D$2:$D$1409,"East",clean_data!$C$2:$C$1409,"Control")/D7,"") -> 0 | I7: =IFERROR(SUMIFS(clean_data!$P$2:$P$1409,clean_data!$D$2:$D$1409,"East",clean_data!$C$2:$C$1409,"Control")/D7,"") -> 0.13924051 | J7: =IFERROR(AVERAGEIFS(clean_data!$T$2:$T$1409,clean_data!$D$2:$D$1409,"East",clean_data!$C$2:$C$1409,"Control"),"") -> 56.628481
A8: Region | B8: East | C8: Treatment | D8: =COUNTIFS(clean_data!$D$2:$D$1409,"East",clean_data!$C$2:$C$1409,"Treatment") -> 172 | E8: =IFERROR(SUMIFS(clean_data!$M$2:$M$1409,clean_data!$D$2:$D$1409,"East",clean_data!$C$2:$C$1409,"Treatment")/D8,"") -> 0.063953488 | F8: =IFERROR(SUMIFS(clean_data!$K$2:$K$1409,clean_data!$D$2:$D$1409,"East",clean_data!$C$2:$C$1409,"Treatment")/D8,"") -> 0.29651163 | G8: =IFERROR(SUMIFS(clean_data!$N$2:$N$1409,clean_data!$D$2:$D$1409,"East",clean_data!$C$2:$C$1409,"Treatment")/D8,"") -> 46.504651 | H8: =IFERROR(SUMIFS(clean_data!$Q$2:$Q$1409,clean_data!$D$2:$D$1409,"East",clean_data!$C$2:$C$1409,"Treatment")/D8,"") -> 0.0058139535 | I8: =IFERROR(SUMIFS(clean_data!$P$2:$P$1409,clean_data!$D$2:$D$1409,"East",clean_data!$C$2:$C$1409,"Treatment")/D8,"") -> 0.26744186 | J8: =IFERROR(AVERAGEIFS(clean_data!$T$2:$T$1409,clean_data!$D$2:$D$1409,"East",clean_data!$C$2:$C$1409,"Treatment"),"") -> 63.168605
A9: Region | B9: West | C9: Control | D9: =COUNTIFS(clean_data!$D$2:$D$1409,"West",clean_data!$C$2:$C$1409,"Control") -> 148 | E9: =IFERROR(SUMIFS(clean_data!$M$2:$M$1409,clean_data!$D$2:$D$1409,"West",clean_data!$C$2:$C$1409,"Control")/D9,"") -> 0.033783784 | F9: =IFERROR(SUMIFS(clean_data!$K$2:$K$1409,clean_data!$D$2:$D$1409,"West",clean_data!$C$2:$C$1409,"Control")/D9,"") -> 0.2972973 | G9: =IFERROR(SUMIFS(clean_data!$N$2:$N$1409,clean_data!$D$2:$D$1409,"West",clean_data!$C$2:$C$1409,"Control")/D9,"") -> 13.684662 | H9: =IFERROR(SUMIFS(clean_data!$Q$2:$Q$1409,clean_data!$D$2:$D$1409,"West",clean_data!$C$2:$C$1409,"Control")/D9,"") -> 0 | I9: =IFERROR(SUMIFS(clean_data!$P$2:$P$1409,clean_data!$D$2:$D$1409,"West",clean_data!$C$2:$C$1409,"Control")/D9,"") -> 0.15540541 | J9: =IFERROR(AVERAGEIFS(clean_data!$T$2:$T$1409,clean_data!$D$2:$D$1409,"West",clean_data!$C$2:$C$1409,"Control"),"") -> 56.898649
A10: Region | B10: West | C10: Treatment | D10: =COUNTIFS(clean_data!$D$2:$D$1409,"West",clean_data!$C$2:$C$1409,"Treatment") -> 179 | E10: =IFERROR(SUMIFS(clean_data!$M$2:$M$1409,clean_data!$D$2:$D$1409,"West",clean_data!$C$2:$C$1409,"Treatment")/D10,"") -> 0.05027933 | F10: =IFERROR(SUMIFS(clean_data!$K$2:$K$1409,clean_data!$D$2:$D$1409,"West",clean_data!$C$2:$C$1409,"Treatment")/D10,"") -> 0.24022346 | G10: =IFERROR(SUMIFS(clean_data!$N$2:$N$1409,clean_data!$D$2:$D$1409,"West",clean_data!$C$2:$C$1409,"Treatment")/D10,"") -> 40.77905 | H10: =IFERROR(SUMIFS(clean_data!$Q$2:$Q$1409,clean_data!$D$2:$D$1409,"West",clean_data!$C$2:$C$1409,"Treatment")/D10,"") -> 0.011173184 | I10: =IFERROR(SUMIFS(clean_data!$P$2:$P$1409,clean_data!$D$2:$D$1409,"West",clean_data!$C$2:$C$1409,"Treatment")/D10,"") -> 0.27374302 | J10: =IFERROR(AVERAGEIFS(clean_data!$T$2:$T$1409,clean_data!$D$2:$D$1409,"West",clean_data!$C$2:$C$1409,"Treatment"),"") -> 63.239106
A13: Device Type
A14: Segment type | B14: Segment | C14: Group | D14: User count | E14: Paid conversion rate | F14: Trial start rate | G14: ARPU | H14: Refund rate | I14: Support ticket rate | J14: Avg engagement score
A15: Device Type | B15: Desktop | C15: Control | D15: =COUNTIFS(clean_data!$F$2:$F$1409,"Desktop",clean_data!$C$2:$C$1409,"Control") -> 200 | E15: =IFERROR(SUMIFS(clean_data!$M$2:$M$1409,clean_data!$F$2:$F$1409,"Desktop",clean_data!$C$2:$C$1409,"Control")/D15,"") -> 0.045 | F15: =IFERROR(SUMIFS(clean_data!$K$2:$K$1409,clean_data!$F$2:$F$1409,"Desktop",clean_data!$C$2:$C$1409,"Control")/D15,"") -> 0.25 | G15: =IFERROR(SUMIFS(clean_data!$N$2:$N$1409,clean_data!$F$2:$F$1409,"Desktop",clean_data!$C$2:$C$1409,"Control")/D15,"") -> 84.94295 | H15: =IFERROR(SUMIFS(clean_data!$Q$2:$Q$1409,clean_data!$F$2:$F$1409,"Desktop",clean_data!$C$2:$C$1409,"Control")/D15,"") -> 0 | I15: =IFERROR(SUMIFS(clean_data!$P$2:$P$1409,clean_data!$F$2:$F$1409,"Desktop",clean_data!$C$2:$C$1409,"Control")/D15,"") -> 0.15 | J15: =IFERROR(AVERAGEIFS(clean_data!$T$2:$T$1409,clean_data!$F$2:$F$1409,"Desktop",clean_data!$C$2:$C$1409,"Control"),"") -> 57.226
A16: Device Type | B16: Desktop | C16: Treatment | D16: =COUNTIFS(clean_data!$F$2:$F$1409,"Desktop",clean_data!$C$2:$C$1409,"Treatment") -> 214 | E16: =IFERROR(SUMIFS(clean_data!$M$2:$M$1409,clean_data!$F$2:$F$1409,"Desktop",clean_data!$C$2:$C$1409,"Treatment")/D16,"") -> 0.065420561 | F16: =IFERROR(SUMIFS(clean_data!$K$2:$K$1409,clean_data!$F$2:$F$1409,"Desktop",clean_data!$C$2:$C$1409,"Treatment")/D16,"") -> 0.27102804 | G16: =IFERROR(SUMIFS(clean_data!$N$2:$N$1409,clean_data!$F$2:$F$1409,"Desktop",clean_data!$C$2:$C$1409,"Treatment")/D16,"") -> 40.958131 | H16: =IFERROR(SUMIFS(clean_data!$Q$2:$Q$1409,clean_data!$F$2:$F$1409,"Desktop",clean_data!$C$2:$C$1409,"Treatment")/D16,"") -> 0 | I16: =IFERROR(SUMIFS(clean_data!$P$2:$P$1409,clean_data!$F$2:$F$1409,"Desktop",clean_data!$C$2:$C$1409,"Treatment")/D16,"") -> 0.23831776 | J16: =IFERROR(AVERAGEIFS(clean_data!$T$2:$T$1409,clean_data!$F$2:$F$1409,"Desktop",clean_data!$C$2:$C$1409,"Treatment"),"") -> 63.214019
A17: Device Type | B17: Mobile | C17: Control | D17: =COUNTIFS(clean_data!$F$2:$F$1409,"Mobile",clean_data!$C$2:$C$1409,"Control") -> 428 | E17: =IFERROR(SUMIFS(clean_data!$M$2:$M$1409,clean_data!$F$2:$F$1409,"Mobile",clean_data!$C$2:$C$1409,"Control")/D17,"") -> 0.025700935 | F17: =IFERROR(SUMIFS(clean_data!$K$2:$K$1409,clean_data!$F$2:$F$1409,"Mobile",clean_data!$C$2:$C$1409,"Control")/D17,"") -> 0.2453271 | G17: =IFERROR(SUMIFS(clean_data!$N$2:$N$1409,clean_data!$F$2:$F$1409,"Mobile",clean_data!$C$2:$C$1409,"Control")/D17,"") -> 41.847967 | H17: =IFERROR(SUMIFS(clean_data!$Q$2:$Q$1409,clean_data!$F$2:$F$1409,"Mobile",clean_data!$C$2:$C$1409,"Control")/D17,"") -> 0 | I17: =IFERROR(SUMIFS(clean_data!$P$2:$P$1409,clean_data!$F$2:$F$1409,"Mobile",clean_data!$C$2:$C$1409,"Control")/D17,"") -> 0.15186916 | J17: =IFERROR(AVERAGEIFS(clean_data!$T$2:$T$1409,clean_data!$F$2:$F$1409,"Mobile",clean_data!$C$2:$C$1409,"Control"),"") -> 57.371729
A18: Device Type | B18: Mobile | C18: Treatment | D18: =COUNTIFS(clean_data!$F$2:$F$1409,"Mobile",clean_data!$C$2:$C$1409,"Treatment") -> 436 | E18: =IFERROR(SUMIFS(clean_data!$M$2:$M$1409,clean_data!$F$2:$F$1409,"Mobile",clean_data!$C$2:$C$1409,"Treatment")/D18,"") -> 0.073394495 | F18: =IFERROR(SUMIFS(clean_data!$K$2:$K$1409,clean_data!$F$2:$F$1409,"Mobile",clean_data!$C$2:$C$1409,"Treatment")/D18,"") -> 0.30963303 | G18: =IFERROR(SUMIFS(clean_data!$N$2:$N$1409,clean_data!$F$2:$F$1409,"Mobile",clean_data!$C$2:$C$1409,"Treatment")/D18,"") -> 58.828349 | H18: =IFERROR(SUMIFS(clean_data!$Q$2:$Q$1409,clean_data!$F$2:$F$1409,"Mobile",clean_data!$C$2:$C$1409,"Treatment")/D18,"") -> 0.0068807339 | I18: =IFERROR(SUMIFS(clean_data!$P$2:$P$1409,clean_data!$F$2:$F$1409,"Mobile",clean_data!$C$2:$C$1409,"Treatment")/D18,"") -> 0.25229358 | J18: =IFERROR(AVERAGEIFS(clean_data!$T$2:$T$1409,clean_data!$F$2:$F$1409,"Mobile",clean_data!$C$2:$C$1409,"Treatment"),"") -> 62.744037
A19: Device Type | B19: Tablet | C19: Control | D19: =COUNTIFS(clean_data!$F$2:$F$1409,"Tablet",clean_data!$C$2:$C$1409,"Control") -> 56 | E19: =IFERROR(SUMIFS(clean_data!$M$2:$M$1409,clean_data!$F$2:$F$1409,"Tablet",clean_data!$C$2:$C$1409,"Control")/D19,"") -> 0.017857143 | F19: =IFERROR(SUMIFS(clean_data!$K$2:$K$1409,clean_data!$F$2:$F$1409,"Tablet",clean_data!$C$2:$C$1409,"Control")/D19,"") -> 0.23214286 | G19: =IFERROR(SUMIFS(clean_data!$N$2:$N$1409,clean_data!$F$2:$F$1409,"Tablet",clean_data!$C$2:$C$1409,"Control")/D19,"") -> 7.3105357 | H19: =IFERROR(SUMIFS(clean_data!$Q$2:$Q$1409,clean_data!$F$2:$F$1409,"Tablet",clean_data!$C$2:$C$1409,"Control")/D19,"") -> 0 | I19: =IFERROR(SUMIFS(clean_data!$P$2:$P$1409,clean_data!$F$2:$F$1409,"Tablet",clean_data!$C$2:$C$1409,"Control")/D19,"") -> 0.10714286 | J19: =IFERROR(AVERAGEIFS(clean_data!$T$2:$T$1409,clean_data!$F$2:$F$1409,"Tablet",clean_data!$C$2:$C$1409,"Control"),"") -> 55.832143
A20: Device Type | B20: Tablet | C20: Treatment | D20: =COUNTIFS(clean_data!$F$2:$F$1409,"Tablet",clean_data!$C$2:$C$1409,"Treatment") -> 56 | E20: =IFERROR(SUMIFS(clean_data!$M$2:$M$1409,clean_data!$F$2:$F$1409,"Tablet",clean_data!$C$2:$C$1409,"Treatment")/D20,"") -> 0.071428571 | F20: =IFERROR(SUMIFS(clean_data!$K$2:$K$1409,clean_data!$F$2:$F$1409,"Tablet",clean_data!$C$2:$C$1409,"Treatment")/D20,"") -> 0.25 | G20: =IFERROR(SUMIFS(clean_data!$N$2:$N$1409,clean_data!$F$2:$F$1409,"Tablet",clean_data!$C$2:$C$1409,"Treatment")/D20,"") -> 73.330536 | H20: =IFERROR(SUMIFS(clean_data!$Q$2:$Q$1409,clean_data!$F$2:$F$1409,"Tablet",clean_data!$C$2:$C$1409,"Treatment")/D20,"") -> 0 | I20: =IFERROR(SUMIFS(clean_data!$P$2:$P$1409,clean_data!$F$2:$F$1409,"Tablet",clean_data!$C$2:$C$1409,"Treatment")/D20,"") -> 0.21428571 | J20: =IFERROR(AVERAGEIFS(clean_data!$T$2:$T$1409,clean_data!$F$2:$F$1409,"Tablet",clean_data!$C$2:$C$1409,"Treatment"),"") -> 63.007143
A21: Device Type | B21: Unknown | C21: Control | D21: =COUNTIFS(clean_data!$F$2:$F$1409,"Unknown",clean_data!$C$2:$C$1409,"Control") -> 9 | E21: =IFERROR(SUMIFS(clean_data!$M$2:$M$1409,clean_data!$F$2:$F$1409,"Unknown",clean_data!$C$2:$C$1409,"Control")/D21,"") -> 0.11111111 | F21: =IFERROR(SUMIFS(clean_data!$K$2:$K$1409,clean_data!$F$2:$F$1409,"Unknown",clean_data!$C$2:$C$1409,"Control")/D21,"") -> 0.66666667 | G21: =IFERROR(SUMIFS(clean_data!$N$2:$N$1409,clean_data!$F$2:$F$1409,"Unknown",clean_data!$C$2:$C$1409,"Control")/D21,"") -> 61.485556 | H21: =IFERROR(SUMIFS(clean_data!$Q$2:$Q$1409,clean_data!$F$2:$F$1409,"Unknown",clean_data!$C$2:$C$1409,"Control")/D21,"") -> 0 | I21: =IFERROR(SUMIFS(clean_data!$P$2:$P$1409,clean_data!$F$2:$F$1409,"Unknown",clean_data!$C$2:$C$1409,"Control")/D21,"") -> 0.11111111 | J21: =IFERROR(AVERAGEIFS(clean_data!$T$2:$T$1409,clean_data!$F$2:$F$1409,"Unknown",clean_data!$C$2:$C$1409,"Control"),"") -> 45.5
A22: Device Type | B22: Unknown | C22: Treatment | D22: =COUNTIFS(clean_data!$F$2:$F$1409,"Unknown",clean_data!$C$2:$C$1409,"Treatment") -> 9 | E22: =IFERROR(SUMIFS(clean_data!$M$2:$M$1409,clean_data!$F$2:$F$1409,"Unknown",clean_data!$C$2:$C$1409,"Treatment")/D22,"") -> 0 | F22: =IFERROR(SUMIFS(clean_data!$K$2:$K$1409,clean_data!$F$2:$F$1409,"Unknown",clean_data!$C$2:$C$1409,"Treatment")/D22,"") -> 0.11111111 | G22: =IFERROR(SUMIFS(clean_data!$N$2:$N$1409,clean_data!$F$2:$F$1409,"Unknown",clean_data!$C$2:$C$1409,"Treatment")/D22,"") -> 0 | H22: =IFERROR(SUMIFS(clean_data!$Q$2:$Q$1409,clean_data!$F$2:$F$1409,"Unknown",clean_data!$C$2:$C$1409,"Treatment")/D22,"") -> 0 | I22: =IFERROR(SUMIFS(clean_data!$P$2:$P$1409,clean_data!$F$2:$F$1409,"Unknown",clean_data!$C$2:$C$1409,"Treatment")/D22,"") -> 0.44444444 | J22: =IFERROR(AVERAGEIFS(clean_data!$T$2:$T$1409,clean_data!$F$2:$F$1409,"Unknown",clean_data!$C$2:$C$1409,"Treatment"),"") -> 62.166667
A25: Traffic Source
A26: Segment type | B26: Segment | C26: Group | D26: User count | E26: Paid conversion rate | F26: Trial start rate | G26: ARPU | H26: Refund rate | I26: Support ticket rate | J26: Avg engagement score
A27: Traffic Source | B27: Email | C27: Control | D27: =COUNTIFS(clean_data!$H$2:$H$1409,"Email",clean_data!$C$2:$C$1409,"Control") -> 74 | E27: =IFERROR(SUMIFS(clean_data!$M$2:$M$1409,clean_data!$H$2:$H$1409,"Email",clean_data!$C$2:$C$1409,"Control")/D27,"") -> 0.027027027 | F27: =IFERROR(SUMIFS(clean_data!$K$2:$K$1409,clean_data!$H$2:$H$1409,"Email",clean_data!$C$2:$C$1409,"Control")/D27,"") -> 0.24324324 | G27: =IFERROR(SUMIFS(clean_data!$N$2:$N$1409,clean_data!$H$2:$H$1409,"Email",clean_data!$C$2:$C$1409,"Control")/D27,"") -> 28.720676 | H27: =IFERROR(SUMIFS(clean_data!$Q$2:$Q$1409,clean_data!$H$2:$H$1409,"Email",clean_data!$C$2:$C$1409,"Control")/D27,"") -> 0 | I27: =IFERROR(SUMIFS(clean_data!$P$2:$P$1409,clean_data!$H$2:$H$1409,"Email",clean_data!$C$2:$C$1409,"Control")/D27,"") -> 0.16216216 | J27: =IFERROR(AVERAGEIFS(clean_data!$T$2:$T$1409,clean_data!$H$2:$H$1409,"Email",clean_data!$C$2:$C$1409,"Control"),"") -> 57.828378
A28: Traffic Source | B28: Email | C28: Treatment | D28: =COUNTIFS(clean_data!$H$2:$H$1409,"Email",clean_data!$C$2:$C$1409,"Treatment") -> 56 | E28: =IFERROR(SUMIFS(clean_data!$M$2:$M$1409,clean_data!$H$2:$H$1409,"Email",clean_data!$C$2:$C$1409,"Treatment")/D28,"") -> 0.071428571 | F28: =IFERROR(SUMIFS(clean_data!$K$2:$K$1409,clean_data!$H$2:$H$1409,"Email",clean_data!$C$2:$C$1409,"Treatment")/D28,"") -> 0.35714286 | G28: =IFERROR(SUMIFS(clean_data!$N$2:$N$1409,clean_data!$H$2:$H$1409,"Email",clean_data!$C$2:$C$1409,"Treatment")/D28,"") -> 44.980893 | H28: =IFERROR(SUMIFS(clean_data!$Q$2:$Q$1409,clean_data!$H$2:$H$1409,"Email",clean_data!$C$2:$C$1409,"Treatment")/D28,"") -> 0 | I28: =IFERROR(SUMIFS(clean_data!$P$2:$P$1409,clean_data!$H$2:$H$1409,"Email",clean_data!$C$2:$C$1409,"Treatment")/D28,"") -> 0.33928571 | J28: =IFERROR(AVERAGEIFS(clean_data!$T$2:$T$1409,clean_data!$H$2:$H$1409,"Email",clean_data!$C$2:$C$1409,"Treatment"),"") -> 62.241071
A29: Traffic Source | B29: Organic | C29: Control | D29: =COUNTIFS(clean_data!$H$2:$H$1409,"Organic",clean_data!$C$2:$C$1409,"Control") -> 246 | E29: =IFERROR(SUMIFS(clean_data!$M$2:$M$1409,clean_data!$H$2:$H$1409,"Organic",clean_data!$C$2:$C$1409,"Control")/D29,"") -> 0.020325203 | F29: =IFERROR(SUMIFS(clean_data!$K$2:$K$1409,clean_data!$H$2:$H$1409,"Organic",clean_data!$C$2:$C$1409,"Control")/D29,"") -> 0.21138211 | G29: =IFERROR(SUMIFS(clean_data!$N$2:$N$1409,clean_data!$H$2:$H$1409,"Organic",clean_data!$C$2:$C$1409,"Control")/D29,"") -> 42.512602 | H29: =IFERROR(SUMIFS(clean_data!$Q$2:$Q$1409,clean_data!$H$2:$H$1409,"Organic",clean_data!$C$2:$C$1409,"Control")/D29,"") -> 0 | I29: =IFERROR(SUMIFS(clean_data!$P$2:$P$1409,clean_data!$H$2:$H$1409,"Organic",clean_data!$C$2:$C$1409,"Control")/D29,"") -> 0.12195122 | J29: =IFERROR(AVERAGEIFS(clean_data!$T$2:$T$1409,clean_data!$H$2:$H$1409,"Organic",clean_data!$C$2:$C$1409,"Control"),"") -> 58.457317
A30: Traffic Source | B30: Organic | C30: Treatment | D30: =COUNTIFS(clean_data!$H$2:$H$1409,"Organic",clean_data!$C$2:$C$1409,"Treatment") -> 241 | E30: =IFERROR(SUMIFS(clean_data!$M$2:$M$1409,clean_data!$H$2:$H$1409,"Organic",clean_data!$C$2:$C$1409,"Treatment")/D30,"") -> 0.062240664 | F30: =IFERROR(SUMIFS(clean_data!$K$2:$K$1409,clean_data!$H$2:$H$1409,"Organic",clean_data!$C$2:$C$1409,"Treatment")/D30,"") -> 0.26556017 | G30: =IFERROR(SUMIFS(clean_data!$N$2:$N$1409,clean_data!$H$2:$H$1409,"Organic",clean_data!$C$2:$C$1409,"Treatment")/D30,"") -> 50.70639 | H30: =IFERROR(SUMIFS(clean_data!$Q$2:$Q$1409,clean_data!$H$2:$H$1409,"Organic",clean_data!$C$2:$C$1409,"Treatment")/D30,"") -> 0 | I30: =IFERROR(SUMIFS(clean_data!$P$2:$P$1409,clean_data!$H$2:$H$1409,"Organic",clean_data!$C$2:$C$1409,"Treatment")/D30,"") -> 0.22821577 | J30: =IFERROR(AVERAGEIFS(clean_data!$T$2:$T$1409,clean_data!$H$2:$H$1409,"Organic",clean_data!$C$2:$C$1409,"Treatment"),"") -> 61.514108
A31: Traffic Source | B31: Paid Search | C31: Control | D31: =COUNTIFS(clean_data!$H$2:$H$1409,"Paid Search",clean_data!$C$2:$C$1409,"Control") -> 156 | E31: =IFERROR(SUMIFS(clean_data!$M$2:$M$1409,clean_data!$H$2:$H$1409,"Paid Search",clean_data!$C$2:$C$1409,"Control")/D31,"") -> 0.012820513 | F31: =IFERROR(SUMIFS(clean_data!$K$2:$K$1409,clean_data!$H$2:$H$1409,"Paid Search",clean_data!$C$2:$C$1409,"Control")/D31,"") -> 0.25641026 | G31: =IFERROR(SUMIFS(clean_data!$N$2:$N$1409,clean_data!$H$2:$H$1409,"Paid Search",clean_data!$C$2:$C$1409,"Control")/D31,"") -> 10.837436 | H31: =IFERROR(SUMIFS(clean_data!$Q$2:$Q$1409,clean_data!$H$2:$H$1409,"Paid Search",clean_data!$C$2:$C$1409,"Control")/D31,"") -> 0 | I31: =IFERROR(SUMIFS(clean_data!$P$2:$P$1409,clean_data!$H$2:$H$1409,"Paid Search",clean_data!$C$2:$C$1409,"Control")/D31,"") -> 0.18589744 | J31: =IFERROR(AVERAGEIFS(clean_data!$T$2:$T$1409,clean_data!$H$2:$H$1409,"Paid Search",clean_data!$C$2:$C$1409,"Control"),"") -> 54.6
A32: Traffic Source | B32: Paid Search | C32: Treatment | D32: =COUNTIFS(clean_data!$H$2:$H$1409,"Paid Search",clean_data!$C$2:$C$1409,"Treatment") -> 176 | E32: =IFERROR(SUMIFS(clean_data!$M$2:$M$1409,clean_data!$H$2:$H$1409,"Paid Search",clean_data!$C$2:$C$1409,"Treatment")/D32,"") -> 0.0625 | F32: =IFERROR(SUMIFS(clean_data!$K$2:$K$1409,clean_data!$H$2:$H$1409,"Paid Search",clean_data!$C$2:$C$1409,"Treatment")/D32,"") -> 0.26136364 | G32: =IFERROR(SUMIFS(clean_data!$N$2:$N$1409,clean_data!$H$2:$H$1409,"Paid Search",clean_data!$C$2:$C$1409,"Treatment")/D32,"") -> 34.781591 | H32: =IFERROR(SUMIFS(clean_data!$Q$2:$Q$1409,clean_data!$H$2:$H$1409,"Paid Search",clean_data!$C$2:$C$1409,"Treatment")/D32,"") -> 0.0056818182 | I32: =IFERROR(SUMIFS(clean_data!$P$2:$P$1409,clean_data!$H$2:$H$1409,"Paid Search",clean_data!$C$2:$C$1409,"Treatment")/D32,"") -> 0.22159091 | J32: =IFERROR(AVERAGEIFS(clean_data!$T$2:$T$1409,clean_data!$H$2:$H$1409,"Paid Search",clean_data!$C$2:$C$1409,"Treatment"),"") -> 62.796023
A33: Traffic Source | B33: Referral | C33: Control | D33: =COUNTIFS(clean_data!$H$2:$H$1409,"Referral",clean_data!$C$2:$C$1409,"Control") -> 81 | E33: =IFERROR(SUMIFS(clean_data!$M$2:$M$1409,clean_data!$H$2:$H$1409,"Referral",clean_data!$C$2:$C$1409,"Control")/D33,"") -> 0.024691358 | F33: =IFERROR(SUMIFS(clean_data!$K$2:$K$1409,clean_data!$H$2:$H$1409,"Referral",clean_data!$C$2:$C$1409,"Control")/D33,"") -> 0.25925926 | G33: =IFERROR(SUMIFS(clean_data!$N$2:$N$1409,clean_data!$H$2:$H$1409,"Referral",clean_data!$C$2:$C$1409,"Control")/D33,"") -> 33.310988 | H33: =IFERROR(SUMIFS(clean_data!$Q$2:$Q$1409,clean_data!$H$2:$H$1409,"Referral",clean_data!$C$2:$C$1409,"Control")/D33,"") -> 0 | I33: =IFERROR(SUMIFS(clean_data!$P$2:$P$1409,clean_data!$H$2:$H$1409,"Referral",clean_data!$C$2:$C$1409,"Control")/D33,"") -> 0.12345679 | J33: =IFERROR(AVERAGEIFS(clean_data!$T$2:$T$1409,clean_data!$H$2:$H$1409,"Referral",clean_data!$C$2:$C$1409,"Control"),"") -> 58.391358
A34: Traffic Source | B34: Referral | C34: Treatment | D34: =COUNTIFS(clean_data!$H$2:$H$1409,"Referral",clean_data!$C$2:$C$1409,"Treatment") -> 91 | E34: =IFERROR(SUMIFS(clean_data!$M$2:$M$1409,clean_data!$H$2:$H$1409,"Referral",clean_data!$C$2:$C$1409,"Treatment")/D34,"") -> 0.10989011 | F34: =IFERROR(SUMIFS(clean_data!$K$2:$K$1409,clean_data!$H$2:$H$1409,"Referral",clean_data!$C$2:$C$1409,"Treatment")/D34,"") -> 0.35164835 | G34: =IFERROR(SUMIFS(clean_data!$N$2:$N$1409,clean_data!$H$2:$H$1409,"Referral",clean_data!$C$2:$C$1409,"Treatment")/D34,"") -> 103.00418 | H34: =IFERROR(SUMIFS(clean_data!$Q$2:$Q$1409,clean_data!$H$2:$H$1409,"Referral",clean_data!$C$2:$C$1409,"Treatment")/D34,"") -> 0.010989011 | I34: =IFERROR(SUMIFS(clean_data!$P$2:$P$1409,clean_data!$H$2:$H$1409,"Referral",clean_data!$C$2:$C$1409,"Treatment")/D34,"") -> 0.28571429 | J34: =IFERROR(AVERAGEIFS(clean_data!$T$2:$T$1409,clean_data!$H$2:$H$1409,"Referral",clean_data!$C$2:$C$1409,"Treatment"),"") -> 64.154945
A35: Traffic Source | B35: Social | C35: Control | D35: =COUNTIFS(clean_data!$H$2:$H$1409,"Social",clean_data!$C$2:$C$1409,"Control") -> 130 | E35: =IFERROR(SUMIFS(clean_data!$M$2:$M$1409,clean_data!$H$2:$H$1409,"Social",clean_data!$C$2:$C$1409,"Control")/D35,"") -> 0.076923077 | F35: =IFERROR(SUMIFS(clean_data!$K$2:$K$1409,clean_data!$H$2:$H$1409,"Social",clean_data!$C$2:$C$1409,"Control")/D35,"") -> 0.31538462 | G35: =IFERROR(SUMIFS(clean_data!$N$2:$N$1409,clean_data!$H$2:$H$1409,"Social",clean_data!$C$2:$C$1409,"Control")/D35,"") -> 136.08715 | H35: =IFERROR(SUMIFS(clean_data!$Q$2:$Q$1409,clean_data!$H$2:$H$1409,"Social",clean_data!$C$2:$C$1409,"Control")/D35,"") -> 0 | I35: =IFERROR(SUMIFS(clean_data!$P$2:$P$1409,clean_data!$H$2:$H$1409,"Social",clean_data!$C$2:$C$1409,"Control")/D35,"") -> 0.14615385 | J35: =IFERROR(AVERAGEIFS(clean_data!$T$2:$T$1409,clean_data!$H$2:$H$1409,"Social",clean_data!$C$2:$C$1409,"Control"),"") -> 56.001538
A36: Traffic Source | B36: Social | C36: Treatment | D36: =COUNTIFS(clean_data!$H$2:$H$1409,"Social",clean_data!$C$2:$C$1409,"Treatment") -> 133 | E36: =IFERROR(SUMIFS(clean_data!$M$2:$M$1409,clean_data!$H$2:$H$1409,"Social",clean_data!$C$2:$C$1409,"Treatment")/D36,"") -> 0.060150376 | F36: =IFERROR(SUMIFS(clean_data!$K$2:$K$1409,clean_data!$H$2:$H$1409,"Social",clean_data!$C$2:$C$1409,"Treatment")/D36,"") -> 0.31578947 | G36: =IFERROR(SUMIFS(clean_data!$N$2:$N$1409,clean_data!$H$2:$H$1409,"Social",clean_data!$C$2:$C$1409,"Treatment")/D36,"") -> 51.552105 | H36: =IFERROR(SUMIFS(clean_data!$Q$2:$Q$1409,clean_data!$H$2:$H$1409,"Social",clean_data!$C$2:$C$1409,"Treatment")/D36,"") -> 0.007518797 | I36: =IFERROR(SUMIFS(clean_data!$P$2:$P$1409,clean_data!$H$2:$H$1409,"Social",clean_data!$C$2:$C$1409,"Treatment")/D36,"") -> 0.27067669 | J36: =IFERROR(AVERAGEIFS(clean_data!$T$2:$T$1409,clean_data!$H$2:$H$1409,"Social",clean_data!$C$2:$C$1409,"Treatment"),"") -> 63.790226
A37: Traffic Source | B37: Unknown | C37: Control | D37: =COUNTIFS(clean_data!$H$2:$H$1409,"Unknown",clean_data!$C$2:$C$1409,"Control") -> 6 | E37: =IFERROR(SUMIFS(clean_data!$M$2:$M$1409,clean_data!$H$2:$H$1409,"Unknown",clean_data!$C$2:$C$1409,"Control")/D37,"") -> 0.16666667 | F37: =IFERROR(SUMIFS(clean_data!$K$2:$K$1409,clean_data!$H$2:$H$1409,"Unknown",clean_data!$C$2:$C$1409,"Control")/D37,"") -> 0.33333333 | G37: =IFERROR(SUMIFS(clean_data!$N$2:$N$1409,clean_data!$H$2:$H$1409,"Unknown",clean_data!$C$2:$C$1409,"Control")/D37,"") -> 199.78167 | H37: =IFERROR(SUMIFS(clean_data!$Q$2:$Q$1409,clean_data!$H$2:$H$1409,"Unknown",clean_data!$C$2:$C$1409,"Control")/D37,"") -> 0 | I37: =IFERROR(SUMIFS(clean_data!$P$2:$P$1409,clean_data!$H$2:$H$1409,"Unknown",clean_data!$C$2:$C$1409,"Control")/D37,"") -> 0.33333333 | J37: =IFERROR(AVERAGEIFS(clean_data!$T$2:$T$1409,clean_data!$H$2:$H$1409,"Unknown",clean_data!$C$2:$C$1409,"Control"),"") -> 58.183333
A38: Traffic Source | B38: Unknown | C38: Treatment | D38: =COUNTIFS(clean_data!$H$2:$H$1409,"Unknown",clean_data!$C$2:$C$1409,"Treatment") -> 18 | E38: =IFERROR(SUMIFS(clean_data!$M$2:$M$1409,clean_data!$H$2:$H$1409,"Unknown",clean_data!$C$2:$C$1409,"Treatment")/D38,"") -> 0.11111111 | F38: =IFERROR(SUMIFS(clean_data!$K$2:$K$1409,clean_data!$H$2:$H$1409,"Unknown",clean_data!$C$2:$C$1409,"Treatment")/D38,"") -> 0.22222222 | G38: =IFERROR(SUMIFS(clean_data!$N$2:$N$1409,clean_data!$H$2:$H$1409,"Unknown",clean_data!$C$2:$C$1409,"Treatment")/D38,"") -> 79.453889 | H38: =IFERROR(SUMIFS(clean_data!$Q$2:$Q$1409,clean_data!$H$2:$H$1409,"Unknown",clean_data!$C$2:$C$1409,"Treatment")/D38,"") -> 0 | I38: =IFERROR(SUMIFS(clean_data!$P$2:$P$1409,clean_data!$H$2:$H$1409,"Unknown",clean_data!$C$2:$C$1409,"Treatment")/D38,"") -> 0.11111111 | J38: =IFERROR(AVERAGEIFS(clean_data!$T$2:$T$1409,clean_data!$H$2:$H$1409,"Unknown",clean_data!$C$2:$C$1409,"Treatment"),"") -> 71.522222
A41: Plan Type
A42: Segment type | B42: Segment | C42: Group | D42: User count | E42: Paid conversion rate | F42: Trial start rate | G42: ARPU | H42: Refund rate | I42: Support ticket rate | J42: Avg engagement score
A43: Plan Type | B43: Basic | C43: Control | D43: =COUNTIFS(clean_data!$I$2:$I$1409,"Basic",clean_data!$C$2:$C$1409,"Control") -> 223 | E43: =IFERROR(SUMIFS(clean_data!$M$2:$M$1409,clean_data!$I$2:$I$1409,"Basic",clean_data!$C$2:$C$1409,"Control")/D43,"") -> 0.035874439 | F43: =IFERROR(SUMIFS(clean_data!$K$2:$K$1409,clean_data!$I$2:$I$1409,"Basic",clean_data!$C$2:$C$1409,"Control")/D43,"") -> 0.23766816 | G43: =IFERROR(SUMIFS(clean_data!$N$2:$N$1409,clean_data!$I$2:$I$1409,"Basic",clean_data!$C$2:$C$1409,"Control")/D43,"") -> 97.800314 | H43: =IFERROR(SUMIFS(clean_data!$Q$2:$Q$1409,clean_data!$I$2:$I$1409,"Basic",clean_data!$C$2:$C$1409,"Control")/D43,"") -> 0 | I43: =IFERROR(SUMIFS(clean_data!$P$2:$P$1409,clean_data!$I$2:$I$1409,"Basic",clean_data!$C$2:$C$1409,"Control")/D43,"") -> 0.14349776 | J43: =IFERROR(AVERAGEIFS(clean_data!$T$2:$T$1409,clean_data!$I$2:$I$1409,"Basic",clean_data!$C$2:$C$1409,"Control"),"") -> 56.924664
A44: Plan Type | B44: Basic | C44: Treatment | D44: =COUNTIFS(clean_data!$I$2:$I$1409,"Basic",clean_data!$C$2:$C$1409,"Treatment") -> 235 | E44: =IFERROR(SUMIFS(clean_data!$M$2:$M$1409,clean_data!$I$2:$I$1409,"Basic",clean_data!$C$2:$C$1409,"Treatment")/D44,"") -> 0.038297872 | F44: =IFERROR(SUMIFS(clean_data!$K$2:$K$1409,clean_data!$I$2:$I$1409,"Basic",clean_data!$C$2:$C$1409,"Treatment")/D44,"") -> 0.28085106 | G44: =IFERROR(SUMIFS(clean_data!$N$2:$N$1409,clean_data!$I$2:$I$1409,"Basic",clean_data!$C$2:$C$1409,"Treatment")/D44,"") -> 36.288596 | H44: =IFERROR(SUMIFS(clean_data!$Q$2:$Q$1409,clean_data!$I$2:$I$1409,"Basic",clean_data!$C$2:$C$1409,"Treatment")/D44,"") -> 0 | I44: =IFERROR(SUMIFS(clean_data!$P$2:$P$1409,clean_data!$I$2:$I$1409,"Basic",clean_data!$C$2:$C$1409,"Treatment")/D44,"") -> 0.24680851 | J44: =IFERROR(AVERAGEIFS(clean_data!$T$2:$T$1409,clean_data!$I$2:$I$1409,"Basic",clean_data!$C$2:$C$1409,"Treatment"),"") -> 62.872766
A45: Plan Type | B45: Free | C45: Control | D45: =COUNTIFS(clean_data!$I$2:$I$1409,"Free",clean_data!$C$2:$C$1409,"Control") -> 361 | E45: =IFERROR(SUMIFS(clean_data!$M$2:$M$1409,clean_data!$I$2:$I$1409,"Free",clean_data!$C$2:$C$1409,"Control")/D45,"") -> 0.030470914 | F45: =IFERROR(SUMIFS(clean_data!$K$2:$K$1409,clean_data!$I$2:$I$1409,"Free",clean_data!$C$2:$C$1409,"Control")/D45,"") -> 0.24930748 | G45: =IFERROR(SUMIFS(clean_data!$N$2:$N$1409,clean_data!$I$2:$I$1409,"Free",clean_data!$C$2:$C$1409,"Control")/D45,"") -> 22.665596 | H45: =IFERROR(SUMIFS(clean_data!$Q$2:$Q$1409,clean_data!$I$2:$I$1409,"Free",clean_data!$C$2:$C$1409,"Control")/D45,"") -> 0 | I45: =IFERROR(SUMIFS(clean_data!$P$2:$P$1409,clean_data!$I$2:$I$1409,"Free",clean_data!$C$2:$C$1409,"Control")/D45,"") -> 0.12188366 | J45: =IFERROR(AVERAGEIFS(clean_data!$T$2:$T$1409,clean_data!$I$2:$I$1409,"Free",clean_data!$C$2:$C$1409,"Control"),"") -> 57.323546
A46: Plan Type | B46: Free | C46: Treatment | D46: =COUNTIFS(clean_data!$I$2:$I$1409,"Free",clean_data!$C$2:$C$1409,"Treatment") -> 368 | E46: =IFERROR(SUMIFS(clean_data!$M$2:$M$1409,clean_data!$I$2:$I$1409,"Free",clean_data!$C$2:$C$1409,"Treatment")/D46,"") -> 0.092391304 | F46: =IFERROR(SUMIFS(clean_data!$K$2:$K$1409,clean_data!$I$2:$I$1409,"Free",clean_data!$C$2:$C$1409,"Treatment")/D46,"") -> 0.31793478 | G46: =IFERROR(SUMIFS(clean_data!$N$2:$N$1409,clean_data!$I$2:$I$1409,"Free",clean_data!$C$2:$C$1409,"Treatment")/D46,"") -> 50.89731 | H46: =IFERROR(SUMIFS(clean_data!$Q$2:$Q$1409,clean_data!$I$2:$I$1409,"Free",clean_data!$C$2:$C$1409,"Treatment")/D46,"") -> 0.0054347826 | I46: =IFERROR(SUMIFS(clean_data!$P$2:$P$1409,clean_data!$I$2:$I$1409,"Free",clean_data!$C$2:$C$1409,"Treatment")/D46,"") -> 0.24184783 | J46: =IFERROR(AVERAGEIFS(clean_data!$T$2:$T$1409,clean_data!$I$2:$I$1409,"Free",clean_data!$C$2:$C$1409,"Treatment"),"") -> 62.229076
...

Sheet Executive summary
A1: Metric | B1: Control | C1: Treatment | D1: Absolute delta | E1: Relative change
A2: User count | B2: =Control_vs_Treatment!B$2 -> 693 | C2: =Control_vs_Treatment!B$3 -> 715 | D2: =C2-B2 -> 22 | E2: =IFERROR(D2/B2,"") -> 0.031746032
A3: Landing page visit rate | B3: =Control_vs_Treatment!C$2 -> 0.63636364 | C3: =Control_vs_Treatment!C$3 -> 0.72587413 | D3: =C3-B3 -> 0.08951049 | E3: =IFERROR(D3/B3,"") -> 0.14065934
A4: Trial start rate | B4: =Control_vs_Treatment!D$2 -> 0.25108225 | C4: =Control_vs_Treatment!D$3 -> 0.29090909 | D4: =C4-B4 -> 0.03982684 | E4: =IFERROR(D4/B4,"") -> 0.15862069
A5: Onboarding completion rate | B5: =Control_vs_Treatment!E$2 -> 0.15584416 | C5: =Control_vs_Treatment!E$3 -> 0.21258741 | D5: =C5-B5 -> 0.056743257 | E5: =IFERROR(D5/B5,"") -> 0.36410256
A6: Paid conversion rate | B6: =Control_vs_Treatment!F$2 -> 0.031746032 | C6: =Control_vs_Treatment!F$3 -> 0.06993007 | D6: =C6-B6 -> 0.038184038 | E6: =IFERROR(D6/B6,"") -> 1.2027972
A7: Average revenue per user | B7: =Control_vs_Treatment!G$2 -> 51.749322 | C7: =Control_vs_Treatment!G$3 -> 53.875119 | D7: =C7-B7 -> 2.1257971 | E7: =IFERROR(D7/B7,"") -> 0.041078743
A8: Average revenue per converted user | B8: =Control_vs_Treatment!H$2 -> 1630.1036 | C8: =Control_vs_Treatment!H$3 -> 770.4142 | D8: =C8-B8 -> -859.68944 | E8: =IFERROR(D8/B8,"") -> -0.5273833
A9: Refund rate | B9: =Control_vs_Treatment!I$2 -> 0 | C9: =Control_vs_Treatment!I$3 -> 0.0041958042 | D9: =C9-B9 -> 0.0041958042 | E9: =IFERROR(D9/B9,"")
A10: Support ticket rate | B10: =Control_vs_Treatment!J$2 -> 0.14718615 | C10: =Control_vs_Treatment!J$3 -> 0.24755245 | D10: =C10-B10 -> 0.1003663 | E10: =IFERROR(D10/B10,"") -> 0.68190045
A11: Average engagement score | B11: =Control_vs_Treatment!K$2 -> 57.051082 | C11: =Control_vs_Treatment!K$3 -> 62.898042 | D11: =C11-B11 -> 5.8469597 | E11: =IFERROR(D11/B11,"") -> 0.10248639
A12: Average days to convert | B12: =Control_vs_Treatment!L$2 -> 8.8636364 | C12: =Control_vs_Treatment!L$3 -> 6.4 | D12: =C12-B12 -> -2.4636364 | E12: =IFERROR(D12/B12,"") -> -0.27794872

Sheet Hypothesis Testing
A1: Input/Output | B1: Value
A2: Control converted users | B2: =COUNTIFS(clean_data!$C$2:$C$1409,"Control",clean_data!$M$2:$M$1409,1) -> 22
A3: Control total users | B3: =COUNTIF(clean_data!$C$2:$C$1409,"Control") -> 693
A4: Control paid conversion rate | B4: =B2/B3 -> 0.031746032
A5: Treatment converted users | B5: =COUNTIFS(clean_data!$C$2:$C$1409,"Treatment",clean_data!$M$2:$M$1409,1) -> 50
A6: Treatment total users | B6: =COUNTIF(clean_data!$C$2:$C$1409,"Treatment") -> 715
A7: Treatment paid conversion rate | B7: =B5/B6 -> 0.06993007
A8: Absolute lift | B8: =B7-B4 -> 0.038184038
A9: Relative lift | B9: =B8/B4 -> 1.2027972
A10: Pooled conversion rate | B10: =(B2+B5)/(B3+B6) -> 0.051136364
A11: Standard error | B11: =SQRT(B10*(1-B10)*(1/B3+1/B6)) -> 0.011742174
A12: Z-statistic | B12: =(B7-B4)/B11 -> 3.2518713
A13: One-tailed p-value | B13: =1 - _xlfn.NORM.S.DIST(B12, TRUE) -> 0.00057323969
A14: Two-tailed p-value | B14: =2 * (1 - _xlfn.NORM.S.DIST(ABS(B12), TRUE)) -> 0.0011464794
A15: Decision at alpha=0.05 | B15: =IF(B13<0.05,"Reject null hypothesis","Fail to reject null hypothesis") -> Reject null hypothesis
A16: Business interpretation | B16: =IF(B13<0.05,"Treatment shows statistically significant improvement in paid conversion rate.","Treatment does not show statistically significant improvement in paid conversion rate.") -> Treatment shows statistically significant improvement in paid conversion rate.

Sheet Guardrail review
A1: Metric | B1: Control | C1: Treatment | D1: Absolute delta | E1: Relative change | F1: Risk assessment
A2: Average revenue per user | B2: ='Executive summary'!B7 -> 51.749322 | C2: ='Executive summary'!C7 -> 53.875119 | D2: ='Executive summary'!D7 -> 2.1257971 | E2: ='Executive summary'!E7 -> 0.041078743 | F2: =IF(C2<B2,"Watch","Acceptable") -> Acceptable
A3: Average revenue per converted user | B3: ='Executive summary'!B8 -> 1630.1036 | C3: ='Executive summary'!C8 -> 770.4142 | D3: ='Executive summary'!D8 -> -859.68944 | E3: ='Executive summary'!E8 -> -0.5273833 | F3: =IF(C3<B3,"Watch","Acceptable") -> Watch
A4: Refund rate | B4: ='Executive summary'!B9 -> 0 | C4: ='Executive summary'!C9 -> 0.0041958042 | D4: ='Executive summary'!D9 -> 0.0041958042 | E4: ='Executive summary'!E9 | F4: =IF(C4>B4,"Watch","Acceptable") -> Watch
A5: Support ticket rate | B5: ='Executive summary'!B10 -> 0.14718615 | C5: ='Executive summary'!C10 -> 0.24755245 | D5: ='Executive summary'!D10 -> 0.1003663 | E5: ='Executive summary'!E10 -> 0.68190045 | F5: =IF(C5>B5,"Watch","Acceptable") -> Watch
A6: Average engagement score | B6: ='Executive summary'!B11 -> 57.051082 | C6: ='Executive summary'!C11 -> 62.898042 | D6: ='Executive summary'!D11 -> 5.8469597 | E6: ='Executive summary'!E11 -> 0.10248639 | F6: =IF(C6<B6,"Watch","Acceptable") -> Acceptable
A7: Average days to convert | B7: ='Executive summary'!B12 -> 8.8636364 | C7: ='Executive summary'!C12 -> 6.4 | D7: ='Executive summary'!D12 -> -2.4636364 | E7: ='Executive summary'!E12 -> -0.27794872 | F7: =IF(C7>B7,"Watch","Acceptable") -> Acceptable

Sheet business_context
A1: Item | B1: Description
A2: Business context | B2: A subscription product tested a new onboarding and activation campaign against the existing experience.
A3: Control | B3: Existing onboarding experience.
A4: Treatment | B4: New campaign experience.
A5: Primary decision | B5: Decide whether to launch, reject, continue testing, or launch only for selected segments.
A6: visited_landing_page | B6: 1 if the user visited the landing page after signup; otherwise 0.
A7: started_trial | B7: 1 if the user started a trial; otherwise 0.
A8: completed_onboarding | B8: 1 if the user completed onboarding; otherwise 0.
A9: converted_to_paid | B9: 1 if the user became a paid customer; otherwise 0.
A10: revenue_30d | B10: Revenue generated within 30 days of signup.
A11: support_tickets_30d | B11: Number of support tickets raised within 30 days.
A12: refund_requested | B12: 1 if the user requested a refund; otherwise 0.
... A14: Guardrail caution | B14: A better conversion rate may still be risky if refunds, support tickets, or low-quality revenue increase.
B26: =COUNTIF(clean_data!C2:C1409,"Control") -> 693
